<?xml version="1.0"?>
<!-- =================================================================================== -->
<!-- |    This document was autogenerated by xacro from rosbot/rosbot.urdf.xacro       | -->
<!-- |    EDITING THIS FILE BY HAND IS NOT RECOMMENDED                                 | -->
<!-- =================================================================================== -->
<robot name="rosbot">
  <material name="Black">
    <color rgba="0.0 0.0 0.0 1.0" />
  </material>
  <material name="Blue">
    <color rgba="0.0 0.0 0.8 1.0" />
  </material>
  <material name="Green">
    <color rgba="0.0 0.8 0.0 1.0" />
  </material>
  <material name="Grey">
    <color rgba="0.5 0.5 0.5 1.0" />
  </material>
  <material name="DarkGrey">
    <color rgba="0.2 0.2 0.2 1.0" />
  </material>
  <material name="Orange">
    <color rgba="1.0 0.4235294117647059 0.0392156862745098 1.0" />
  </material>
  <material name="Brown">
    <color rgba="0.8705882352941177 0.8117647058823529 0.7647058823529411 1.0" />
  </material>
  <material name="Red">
    <color rgba="0.8 0.0 0.0 1.0" />
  </material>
  <material name="White">
    <color rgba="1.0 1.0 1.0 1.0" />
  </material>
  <link name="base_link" />
  <link name="body_link">
    <visual>
      <geometry>
        <mesh filename="file:/robot_model/meshes/body.stl" scale="0.001 0.001 0.001" />
      </geometry>
      <origin rpy="1.5707963267948966 0.0 1.5707963267948966" xyz="0.0 0.0 -0.02" />
      <material name="White" />
    </visual>
    <collision>
      <geometry>
        <box size="0.197 0.150 0.080" />
      </geometry>
      <origin rpy="0.0 0.0 0.0" xyz="0.0 0.0 0.02" />
    </collision>
    <inertial>
      <mass value="2.0" />
      <inertia ixx="0.001" ixy="0.000" ixz="0.000" iyy="0.001" iyz="0.000" izz="0.001" />
    </inertial>
  </link>
  <link name="cover_link">
    <visual>
      <geometry>
        <mesh filename="file:/robot_model/meshes/cover.stl" scale="0.001 0.001 0.001" />
      </geometry>
      <origin rpy="1.5707963267948966 0.0 1.5707963267948966" xyz="0.0 0.0 -0.002" />
      <material name="Red" />
    </visual>
    <inertial>
      <mass value="0.000001" />
      <inertia ixx="1.0" ixy="0.0" ixz="0.0" iyy="1.0" iyz="0.0" izz="0.0" />
    </inertial>
  </link>
  <link name="imu_link">
    <inertial>
      <mass value="0.001" />
      <inertia ixx="1" ixy="0" ixz="0" iyy="1" iyz="0" izz="1" />
    </inertial>
  </link>
  <link name="camera_link">
    <inertial>
      <mass value="0.000001" />
      <inertia ixx="1" ixy="0" ixz="0" iyy="1" iyz="0" izz="1" />
    </inertial>
  </link>
  <joint name="base_link_to_body_joint" type="fixed">
    <origin rpy="0.0 0.0 0.0" xyz="0.0 0.0 0.0425" />
    <parent link="base_link" />
    <child link="body_link" />
  </joint>
  <joint name="body_to_cover_joint" type="fixed">
    <origin rpy="0.0 0.0 0.0" xyz="0.0 0.0 0.060" />
    <parent link="body_link" />
    <child link="cover_link" />
  </joint>
  <joint name="body_link_to_imu_link_joint" type="fixed">
    <origin rpy="0.0 0.0 0.0" xyz="-0.1369 -0.0419 0.0370" />
    <parent link="body_link" />
    <child link="imu_link" />
  </joint>
  <joint name="body_link_to_camera_link_joint" type="fixed">
    <origin rpy="0.0 0.0 0.0" xyz="-0.0141 0.0 0.125" />
    <parent link="body_link" />
    <child link="camera_link" />
  </joint>
  <joint name="range_left_front_joint" type="fixed">
    <axis xyz="0 1 0" />
    <origin rpy="0 0 0.13 " xyz="0.1 0.05 0.01" />
    <parent link="body_link" />
    <child link="range_left_front" />
  </joint>
  <link name="range_left_front" />
  <joint name="range_right_front_joint" type="fixed">
    <axis xyz="0 1 0" />
    <origin rpy="0 0 -0.13 " xyz="0.1 -0.05 0.01" />
    <parent link="body_link" />
    <child link="range_right_front" />
  </joint>
  <link name="range_right_front" />
  <joint name="range_left_rear_joint" type="fixed">
    <axis xyz="0 1 0" />
    <origin rpy="0 0 3.01 " xyz="-0.1 0.05 0.01" />
    <parent link="body_link" />
    <child link="range_left_rear" />
  </joint>
  <link name="range_left_rear" />
  <joint name="range_right_rear_joint" type="fixed">
    <axis xyz="0 1 0" />
    <origin rpy="0 0 3.27 " xyz="-0.1 -0.05 0.01" />
    <parent link="body_link" />
    <child link="range_right_rear" />
  </joint>
  <link name="range_right_rear" />
  <link name="front_left_wheel_link">
    <visual>
      <geometry>
        <mesh filename="file:/robot_model/meshes/wheel.stl" scale="0.001 0.001 0.001" />
      </geometry>
      <origin rpy="0.0 0.0 1.5707963267948966" xyz="0.0 0.012999999999999998 0.0" />
      <material name="Black" />
    </visual>
    <collision>
      <geometry>
        <cylinder length="0.036" radius="0.0425" />
      </geometry>
      <origin rpy="1.5707963267948966 0.0 0.0" xyz="0.0 0.0 0.0" />
    </collision>
    <inertial>
      <mass value="0.100" />
      <inertia ixx="0.001" ixy="0.000" ixz="0.000" iyy="0.001" iyz="0.000" izz="0.001" />
    </inertial>
  </link>
  <joint name="front left wheel motor" type="continuous">
    <parent link="body_link" />
    <child link="front_left_wheel_link" />
    <origin rpy="0.0 0.0 0.0" xyz="0.053 0.096 0.0" />
    <axis xyz="0.0 1.0 0.0" />
    <limit effort="1.5" velocity="5.0" />
    <dynamics damping="0.001" friction="0.001" />
  </joint>
  <link name="front_right_wheel_link">
    <visual>
      <geometry>
        <mesh filename="file:/robot_model/meshes/wheel.stl" scale="0.001 0.001 0.001" />
      </geometry>
      <origin rpy="0.0 0.0 -1.5707963267948966" xyz="0.0 -0.012999999999999998 0.0" />
      <material name="Black" />
    </visual>
    <collision>
      <geometry>
        <cylinder length="0.036" radius="0.0425" />
      </geometry>
      <origin rpy="1.5707963267948966 0.0 0.0" xyz="0.0 0.0 0.0" />
    </collision>
    <inertial>
      <mass value="0.100" />
      <inertia ixx="0.001" ixy="0.000" ixz="0.000" iyy="0.001" iyz="0.000" izz="0.001" />
    </inertial>
  </link>
  <joint name="front right wheel motor" type="continuous">
    <parent link="body_link" />
    <child link="front_right_wheel_link" />
    <origin rpy="0.0 0.0 0.0" xyz="0.053 -0.096 0.0" />
    <axis xyz="0.0 1.0 0.0" />
    <limit effort="1.5" velocity="5.0" />
    <dynamics damping="0.001" friction="0.001" />
  </joint>
  <link name="rear_left_wheel_link">
    <visual>
      <geometry>
        <mesh filename="file:/robot_model/meshes/wheel.stl" scale="0.001 0.001 0.001" />
      </geometry>
      <origin rpy="0.0 0.0 1.5707963267948966" xyz="0.0 0.012999999999999998 0.0" />
      <material name="Black" />
    </visual>
    <collision>
      <geometry>
        <cylinder length="0.036" radius="0.0425" />
      </geometry>
      <origin rpy="1.5707963267948966 0.0 0.0" xyz="0.0 0.0 0.0" />
    </collision>
    <inertial>
      <mass value="0.100" />
      <inertia ixx="0.001" ixy="0.000" ixz="0.000" iyy="0.001" iyz="0.000" izz="0.001" />
    </inertial>
  </link>
  <joint name="rear left wheel motor" type="continuous">
    <parent link="body_link" />
    <child link="rear_left_wheel_link" />
    <origin rpy="0.0 0.0 0.0" xyz="-0.053 0.096 0.0" />
    <axis xyz="0.0 1.0 0.0" />
    <limit effort="1.5" velocity="5.0" />
    <dynamics damping="0.001" friction="0.001" />
  </joint>
  <link name="rear_right_wheel_link">
    <visual>
      <geometry>
        <mesh filename="file:/robot_model/meshes/wheel.stl" scale="0.001 0.001 0.001" />
      </geometry>
      <origin rpy="0.0 0.0 -1.5707963267948966" xyz="0.0 -0.012999999999999998 0.0" />
      <material name="Black" />
    </visual>
    <collision>
      <geometry>
        <cylinder length="0.036" radius="0.0425" />
      </geometry>
      <origin rpy="1.5707963267948966 0.0 0.0" xyz="0.0 0.0 0.0" />
    </collision>
    <inertial>
      <mass value="0.100" />
      <inertia ixx="0.001" ixy="0.000" ixz="0.000" iyy="0.001" iyz="0.000" izz="0.001" />
    </inertial>
  </link>
  <joint name="rear right wheel motor" type="continuous">
    <parent link="body_link" />
    <child link="rear_right_wheel_link" />
    <origin rpy="0.0 0.0 0.0" xyz="-0.053 -0.096 0.0" />
    <axis xyz="0.0 1.0 0.0" />
    <limit effort="1.5" velocity="5.0" />
    <dynamics damping="0.001" friction="0.001" />
  </joint>
  <link name="lidar_link">
    <visual>
      <geometry>
        <mesh filename="file:/robot_model/meshes/rplidar.stl" scale="0.001 0.001 0.001" />
      </geometry>
      <origin rpy="1.5707963267948966 0.0 1.5707963267948966" xyz="0.0 0.0 0.0" />
      <material name="Black" />
    </visual>
    <collision>
      <geometry>
        <cylinder length="0.0408" radius="0.03625" />
      </geometry>
      <origin rpy="0 0 0" xyz="0 0 0.0204" />
    </collision>
    <inertial>
      <mass value="0.190" />
      <inertia ixx="0.001" ixy="0" ixz="0" iyy="0.001" iyz="0" izz="0.001" />
    </inertial>
  </link>
  <link name="lidar_link_laser_link" />
  <joint name="body_link_to_lidar_link_joint" type="fixed">
    <origin rpy="0.0 0.0 -3.141592653589793" xyz="0.02 0.0 0.0" />
    <parent link="cover_link" />
    <child link="lidar_link" />
  </joint>
  <joint name="lidar_link_laser_link_joint" type="fixed">
    <origin rpy="0 0 0" xyz="0 0 0.0335" />
    <parent link="lidar_link" />
    <child link="lidar_link_laser_link" />
  </joint>
  <link name="orbbec_astra_link">
    <visual>
      <geometry>
        <mesh filename="file:/robot_model/meshes/astra.stl" scale="0.001 0.001 0.001" />
      </geometry>
      <origin rpy="1.5707963267948966 0 1.5707963267948966" xyz="-0.01 0 0.025" />
      <material name="Black" />
    </visual>
    <collision>
      <geometry>
        <box size="0.165 0.04 0.05" />
      </geometry>
      <origin rpy="0 0 1.5707963267948966" xyz="-0.01 0 0.025" />
    </collision>
    <inertial>
      <mass value="0.105" />
      <inertia ixx="0.001" ixy="0" ixz="0" iyy="0.001" iyz="0" izz="0.001" />
    </inertial>
  </link>
  <link name="orbbec_astra_depth_link" />
  <link name="orbbec_astra_depth_refference_link" />
  <joint name="body_link_to_orbbec_astra_link_joint" type="fixed">
    <origin rpy="0.0 0.0 0.0" xyz="0.0 0.0 0.0" />
    <parent link="camera_link" />
    <child link="orbbec_astra_link" />
  </joint>
  <joint name="orbbec_astra_depth_link_joint" type="fixed">
    <origin rpy="0.0 1.5707963267948966 0.0" xyz="0.01 0 0.035" />
    <parent link="orbbec_astra_link" />
    <child link="orbbec_astra_depth_link" />
  </joint>
  <joint name="orbbec_astra_depth_link_refference_joint" type="fixed">
    <origin rpy="1.5707963267948966 -1.5707963267948966 0.0" xyz="0.0 0.0 0.0" />
    <parent link="orbbec_astra_depth_link" />
    <child link="orbbec_astra_depth_refference_link" />
  </joint>
</robot>